Workbook

Sheet MOMO,AIRTEL,CARDS
A3: ITEMS | B3: 44204 | C3: 44965 | D3: 44993 | E3: 45024 | F3: 45054 | G3: 45085 | H3: 45115 | I3: 45146 | J3: 45177 | K3: 45207 | L3: 45238 | M3: 45268 | N3: 13/8/23 | O3: 14/8/23 | P3: 15/8/23 | Q3: 16/8/23 | R3: 17/8/23 | S3: 18/8/23 | T3: 19/8/23 | U3: 20/8/23 | V3: 21/8/23 | W3: 22/8/23 | X3: 23/8/23 | Y3: 24/8/23 | Z3: 25/8/23 | AA3: 26/8/23 | AB3: 27/8/23 | AC3: 28/8/23 | AD3: 29/8/23 | AE3: 30/8/23 | AF3: 31/8/23 | AG3: MONTHLY TOTAL | AH3: 45170 | AI3: =AH3+1 | AJ3: =AI3+1 | AK3: =AJ3+1 | AL3: =AK3+1 | AM3: =AL3+1 | AN3: =AM3+1 | AO3: =AN3+1 | AP3: =AO3+1 | ... BK3: =BJ3+1 | BL3: Monthly Total | BM3: =AH3+30 | BN3: =AI3+30 | BO3: =AJ3+30 | BP3: =AK3+30 | BQ3: =AL3+30 | BR3: =AM3+30 | BS3: =AN3+30 | BT3: =AO3+30 | ... CP3: =BK3+30 | CQ3: =BM3+30 | CR3: Monthly total | CS3: =BN3+30 | CT3: =BO3+30 | CU3: =BP3+30 | CV3: =BQ3+30 | CW3: =BR3+30 | CX3: =BS3+30 | CY3: =BT3+30 | CZ3: =BU3+30 | ... DV3: =CQ3+30 | DW3: MONTHLY TOTAL | DX3: 45261 | DY3: =DX3+1 | DZ3: =DY3+1 | EA3: =DZ3+1 | EB3: =EA3+1 | EC3: =EB3+1 | ED3: =EC3+1 | EE3: =ED3+1 | EF3: =EE3+1 | ... FB3: =FA3+1 | FC3: MONTHLY TOTAL | FD3: =FB3+1 | FE3: =FD3+1 | FF3: =FE3+1 | FG3: =FF3+1 | FH3: =FG3+1 | FI3: =FH3+1 | FJ3: =FI3+1 | FK3: =FJ3+1 | FL3: =FK3+1 | ... GH3: =GG3+1 | GI3: MONTHLY TOTAL | GJ3: =GH3+1 | GK3: =GJ3+1 | GL3: =GK3+1 | GM3: =GL3+1 | GN3: =GM3+1 | GO3: =GN3+1 | GP3: =GO3+1 | GQ3: =GP3+1 | GR3: =GQ3+1 | ... HJ3: =HI3+1 | HK3: 45350 | HL3: 45351 | HM3: MONTHLY TOTAL | HN3: =HL3+1 | HO3: =HN3+1 | HP3: =HO3+1 | HQ3: =HP3+1 | HR3: =HQ3+1 | HS3: =HR3+1 | HT3: =HS3+1 | HU3: =HT3+1 | HV3: =HU3+1 | ... IR3: =IQ3+1 | IS3: monthly total | IT3: 45383 | IU3: =IT3+1 | IV3: =IU3+1 | IW3: =IV3+1 | IX3: =IW3+1 | IY3: =IX3+1 | IZ3: =IY3+1 | JA3: =IZ3+1 | JB3: =JA3+1 | ... JW3: =JV3+1 | JX3: total | JY3: 45413 | JZ3: =JY3+1 | KA3: =JZ3+1 | KB3: =KA3+1 | KC3: =KB3+1 | KD3: =KC3+1 | KE3: =KD3+1 | KF3: =KE3+1 | KG3: =KF3+1 | ... LC3: =LB3+1 | LD3: total | LE3: 1st -june | LF3: 2nd -june | LG3: 3rd -june | LH3: 4th -june | LI3: 5th -june | LJ3: 6th -june | LK3: 7th -june | LL3: 8th -june | LM3: 9th -june | LN3: 10th -june | LO3: 11th -june | LP3: 12th -june | LQ3: 13th -june | LR3: 14th -june | LS3: 15th -june | LT3: 16th -june | LU3: 17th -june | LV3: 18th -june | LW3: 19th -june | LX3: 20th -june | LY3: 21st -june | LZ3: 22nd -june | MA3: 23rd -june | MB3: 24th -june | MC3: 25th -june | MD3: 26th -june | ME3: 27th -june | MF3: 28th -june | MG3: 29th -june | MH3: 30th -june | MI3: total | MJ3: 1st july | MK3: 2nd july | ML3: 3rd july | MM3: 4th july | MN3: 5th july | MO3: 6th july | MP3: 7th july | MQ3: 8th july | MR3: 9th july | MS3: 10th july | MT3: 11th july | MU3: 12th july | MV3: 13th july | MW3: 14th july | MX3: 15th july | MY3: 16th july | MZ3: 17th july | NA3: 18th july | NB3: 19th july | NC3: 20th july | ND3: 21st july | NE3: 22nd july | NF3: 23rd july | NG3: 24th july | NH3: 25th july | NI3: 26th july | NJ3: 27th july | NK3: 28th july | NL3: 29th july | NM3: 30th july | NN3: 31st july | NO3: total | NP3: 1st august | NQ3: 2nd august | NR3: 3rd august | NS3: 4th august | NT3: 5th august | NU3: 6th august | NV3: 7th august | NW3: 8th august | NX3: 9th august | NY3: 10th august | NZ3: 11th august | OA3: 12th august | OB3: 13th august | OC3: 14th august | OD3: 15th august | OE3: 16th august | OF3: 17th august | OG3: 18th august | OH3: 19th august | OI3: 20th august | OJ3: 21st august | OK3: 22nd august | OL3: 23rd august | OM3: 24th august | ON3: 25th august | OO3: 26th august | OP3: 27th august | OQ3: 28th august | OR3: 29th august | OS3: 30th august | OT3: 31st august | OU3: total | OV3: 1st sep | OW3: 2nd sep | OX3: 3rd sep | OY3: 4th sep | OZ3: 5th sep | PA3: 6th sep | PB3: 7th sep | PC3: 8th sep | PD3: 9th sep | PE3: 10th sep | PF3: 11th sep | PG3: 12th sep | PH3: 13th sep | PI3: 14th sep | PJ3: 15th sep | PK3: 16th sep | PL3: 17th sep | PM3: 18th sep | PN3: 19th sep | PO3: 20th sep | PP3: 21st sep | PQ3: 22nd sep | PR3: 23rd sep | PS3: 24th sep | PT3: 25th sep | PU3: 26th sep | PV3: 27th sep | PW3: 28th sep | PX3: 29th sep | PY3: 30th sep | PZ3: total | QA3: 1st oct-24 | QB3: 2nd oct-24 | QC3: 3rd oct-24 | QD3: 4th oct-24 | QE3: 5th oct-24 | QF3: 6th oct-24 | QG3: 7th oct-24 | QH3: 8th oct-24 | QI3: 9th oct-24 | QJ3: 10th oct-24 | QK3: 11th oct-24 | QL3: 12th oct-24 | QM3: 13th oct-24 | QN3: 14th oct-24 | QO3: 15th oct-24 | QP3: 16th oct-24 | QQ3: 17th oct-24 | QR3: 18th oct-24 | QS3: 19th oct-24 | QT3: 20th oct-24 | QU3: 21st oct-24 | QV3: 22nd oct-24 | QW3: 23rd oct-24 | QX3: 24th oct-24 | QY3: 25th oct-24 | QZ3: 26th oct-24 | RA3: 27th oct-24 | RB3: 28th oct-24 | RC3: 29th oct-24 | RD3: 30th oct-24 | RE3: 31st oct-24 | RF3: total | RG3: 1st nov-2024 | RH3: 2nd nov-2024 | RI3: 3rd nov-2024 | RJ3: 4th nov-2024 | RK3: 5th nov-2024 | RL3: 6th nov-2024 | RM3: 7th nov-2024 | RN3: 8th nov-2024 | RO3: 9th nov-2024 | RP3: 10th nov-2024 | RQ3: 11th nov-2024 | RR3: 12th nov-2024 | RS3: 13th nov-2024 | RT3: 14th nov-2024 | RU3: 15th nov-2024 | RV3: 16th nov-2024 | RW3: 17th nov-2024 | RX3: 18th nov-2024 | RY3: 19th nov-2024 | RZ3: 20th nov-2024 | SA3: 21st nov-2024 | SB3: 22nd nov-2024 | SC3: 23rd nov-2024 | SD3: 24th nov-2024 | SE3: 25th nov-2024 | SF3: 26th nov-2024 | SG3: 27th nov-2024 | SH3: 28th nov-2024 | SI3: 29th nov-2024 | SJ3: 30th nov-2024 | SK3: total | SL3: 1st dec-2024 | SM3: 2nd dec-2024 | SN3: 3rd dec-2024 | SO3: 4th dec-2024 | SP3: 5th dec-2024 | SQ3: 6th dec-2024 | SR3: 7th dec-2024 | SS3: 8th dec-2024 | ST3: 9th dec-2024 | SU3: 10th dec-2024 | SV3: 11th dec-2024 | SW3: 12th dec-2024 | SX3: 13th dec-2024 | SY3: 14th dec-2024 | SZ3: 15th dec-2024 | TA3: 16th dec-2024 | TB3: 17th dec-2024 | TC3: 18th dec-2024 | TD3: 19th dec-2024 | TE3: 20th dec-2024 | TF3: 21st dec-2024 | TG3: 22nd dec-2024 | TH3: 23rd dec-2024 | TI3: 24th dec-2024 | TJ3: 25th dec-2024 | TK3: 26th dec-2024 | TL3: 27th dec-2024 | TM3: 28th dec-2024 | TN3: 29th dec-2024 | TO3: 30th dec-2024 | TP3: 31st dec-2024 | TQ3: total | TR3: 1st jan -2025 | TS3: 2nd jan -2025 | TT3: 3rd jan -2025 | TU3: 4th jan -2025 | TV3: 5th jan -2025 | TW3: 6th jan -2025 | TX3: 7th jan -2025 | TY3: 8th jan -2025 | TZ3: 9th jan -2025 | UA3: 10th jan -2025 | UB3: 11th jan -2025 | UC3: 12th jan -2025 | UD3: 13th jan -2025 | UE3: 14th jan -2025 | UF3: 15th jan -2025 | UG3: 16th jan -2025 | UH3: 17th jan -2025 | UI3: 18th jan -2025 | UJ3: 19th jan -2025 | UK3: 20th jan -2025 | UL3: 21st jan -2025 | UM3: 22nd jan -2025 | UN3: 23rd jan -2025 | UO3: 24th jan -2025 | UP3: 25th jan -2025 | UQ3: 26th jan -2025 | UR3: 27th jan -2025 | US3: 28th jan -2025 | UT3: 29th jan -2025 | UU3: 30th jan -2025 | UV3: 31st jan -2025 | UW3: tptal | UX3: 1st feb 2025 | UY3: 2nd feb 2025 | UZ3: 3rd feb 2025 | VA3: 4th feb 2025 | VB3: 5th feb 2025 | VC3: 6th feb 2025 | VD3: 7th feb 2025 | VE3: 8th feb 2025 | VF3: 9th feb 2025 | VG3: 10th feb 2025 | VH3: 11th feb 2025 | VI3: 12th feb 2025 | VJ3: 13th feb 2025 | VK3: 14th feb 2025 | VL3: 15th feb 2025 | VM3: 16th feb 2025 | VN3: 17th feb 2025 | VO3: 18th feb 2025 | VP3: 19th feb 2025 | VQ3: 20th feb 2025 | VR3: 21st feb 2025 | VS3: 22nd feb 2025 | VT3: 23rd feb 2025 | VU3: 24th feb 2025 | VV3: 25th feb 2025 | VW3: 26th feb 2025 | VX3: 27th feb 2025 | VY3: 28th feb 2025 | VZ3: Total | WA3: 1st mar 2025 | WB3: 2nd mar 2025 | WC3: 3rd mar 2025 | WD3: 4th mar 2025 | WE3: 5th mar 2025 | WF3: 6th mar 2025 | WG3: 7th mar 2025 | WH3: 8th mar 2025 | WI3: 9th mar 2025 | WJ3: 10th mar 2025 | WK3: 11th mar 2025 | WL3: 12th mar 2025 | WM3: 13th mar 2025 | WN3: 14th mar 2025 | WO3: 15th mar 2025 | WP3: 16th mar 2025 | WQ3: 17th mar 2025 | WR3: 18th mar 2025 | WS3: 19th mar 2025 | WT3: 20th mar 2025 | WU3: 21st mar 2025 | WV3: 22nd mar 2025 | WW3: 23rd mar 2025 | WX3: 24th mar 2025 | WY3: 25th mar 2025 | WZ3: 26th mar 2025 | XA3: 27th mar 2025 | XB3: 28th mar 2025 | XC3: 29th mar 2025 | XD3: 30th mar 2025 | XE3: 31st mar 2025 | XF3: T0tal | XG3: 1st -apr2025 | XH3: 2nd -apr2025 | XI3: 3rd -apr2025 | XJ3: 4th -apr2025 | XK3: 5th -apr2025 | XL3: 6th -apr2025 | XM3: 7th -apr2025 | XN3: 8th -apr2025 | XO3: 9th -apr2025 | XP3: 10th -apr2025 | XQ3: 11th -apr2025 | XR3: 12th -apr2025 | XS3: 13th -apr2025 | XT3: 14th -apr2025 | XU3: 15th -apr2025 | XV3: 16th -apr2025 | XW3: 17th -apr2025 | XX3: 18th -apr2025 | XY3: 19th -apr2025 | XZ3: 20th -apr2025 | YA3: 21st -apr2025 | YB3: 22nd -apr2025 | YC3: 23rd -apr2025 | YD3: 24th -apr2025 | YE3: 25th -apr2025 | YF3: 26th -apr2025 | YG3: 27th -apr2025 | YH3: 28th -apr2025 | YI3: 29th -apr2025 | YJ3: 30th -apr2025 | YK3: T0tal | YL3: 1st May-2025 | YM3: 2nd May-2025 | YN3: 3rd May-2025 | YO3: 4th May-2025 | YP3: 5th May-2025 | YQ3: 6th May-2025 | YR3: 7th May-2025 | YS3: 8th May-2025 | YT3: 9th May-2025 | YU3: 10th May-2025 | YV3: 11th May-2025 | YW3: 12th May-2025 | YX3: 13th May-2025 | YY3: 14th May-2025 | YZ3: 15th May-2025 | ZA3: 16th May-2025 | ZB3: 17th May-2025 | ZC3: 18th May-2025 | ZD3: 19th May-2025 | ZE3: 20th May-2025 | ZF3: 21st May-2025 | ZG3: 22nd May-2025 | ZH3: 23rd May-2025 | ZI3: 24th May-2025 | ZJ3: 25th May-2025 | ZK3: 26th May-2025 | ZL3: 27th May-2025 | ZM3: 28th May-2025 | ZN3: 29th May-2025 | ZO3: 30th May-2025 | ZP3: 31st May-2025 | ZQ3: T0tal | ZR3: 1st june | ZS3: 2nd june | ZT3: 3rd june | ZU3: 4th june | ZV3: 5th june | ZW3: 6th june | ZX3: 7th june | ZY3: 8th june | ZZ3: 9th june | AAA3: 10th june | AAB3: 11th june | AAC3: 12th june | AAD3: 13th june | AAE3: 14th june | AAF3: 15th june | AAG3: 16th june | AAH3: 17th june | AAI3: 18th june | AAJ3: 19th june | AAK3: 20th june | AAL3: 21st june | AAM3: 22nd june | AAN3: 23rd june | AAO3: 24th june | AAP3: 25th june | AAQ3: 26th june | AAR3: 27th june | AAS3: 28th june | AAT3: 29th june | AAU3: 30th june | AAV3: T0tal | AAW3: 1st july | AAX3: 2nd july | AAY3: 3rd july | AAZ3: 4th july | ABA3: 5th july | ABB3: 6th july | ABC3: 7th july | ABD3: 8th july | ABE3: 9th july | ABF3: 10th july | ABG3: 11th july | ABH3: 12th july | ABI3: 13th july | ABJ3: 14th july | ABK3: 15th july | ABL3: 16th july | ABM3: 17th july | ABN3: 18th july | ABO3: 19th july | ABP3: 20th july | ABQ3: 21st july | ABR3: 22nd july | ABS3: 23rd july | ABT3: 24th july | ABU3: 25th july | ABV3: 26th july | ABW3: 27th july | ABX3: 28th july | ABY3: 29th july | ABZ3: 30th july | ACA3: 31st july | ACB3: T0tal | ACC3: 1st aug | ACD3: 2nd aug | ACE3: 3rd aug | ACF3: 4th aug | ACG3: 5th aug | ACH3: 6th aug | ACI3: 7th aug | ACJ3: 8th aug | ACK3: 9th aug | ACL3: 10th aug | ACM3: 11th aug | ACN3: 12th aug | ACO3: 13th aug | ACP3: 14th aug | ACQ3: 15th aug | ACR3: 16th aug | ACS3: 17th aug | ACT3: 18th aug | ACU3: 19th aug | ACV3: 20th aug | ACW3: 21st aug | ACX3: 22nd aug | ACY3: 23rd aug | ACZ3: 24th aug | ADA3: 25th aug | ADB3: 26th aug | ADC3: 27th aug | ADD3: 28th aug | ADE3: 29th aug | ADF3: 30th aug | ADG3: 31st aug | ADI3: 1st -sep25 | ADJ3: 2nd -sep25 | ADK3: 3rd -sep25 | ADL3: 4th -sep25 | ADM3: 5th -sep25 | ADN3: 6th -sep25 | ADO3: 7th -sep25 | ADP3: 8th -sep25 | ADQ3: 9th -sep25 | ADR3: 10th -sep25 | ADS3: 11th -sep25 | ADT3: 12th -sep25 | ADU3: 13th -sep25 | ADV3: 14th -sep25 | ADW3: 15th -sep25 | ADX3: 16th -sep25 | ADY3: 17th -sep25 | ADZ3: 18th -sep25 | AEA3: 19th -sep25 | AEB3: 20th -sep25 | AEC3: 21st -sep25 | AED3: 22nd -sep25 | AEE3: 23rd -sep25 | AEF3: 24th -sep25 | AEG3: 25th -sep25 | AEH3: 26th -sep25 | AEI3: 27th -sep25 | AEJ3: 28th -sep25 | AEK3: 29th -sep25 | AEL3: 30th -sep25 | AEM3: Total | AEN3: 1st -oct25 | AEO3: 2nd -oct25 | AEP3: 3rd -oct25 | AEQ3: 4th -oct25 | AER3: 5th -oct25 | AES3: 6th -oct25 | AET3: 7th -oct25 | AEU3: 8th -oct25 | AEV3: 9th -oct25 | AEW3: 10th -oct25 | AEX3: 11th -oct25 | AEY3: 12th -oct25 | AEZ3: 13th -oct25 | AFA3: 14th -oct25 | AFB3: 15th -oct25 | AFC3: 16th -oct25 | AFD3: 17th -oct25 | AFE3: 18th -oct25 | AFF3: 19th -oct25 | AFG3: 20th -oct25 | AFH3: 21st -oct25 | AFI3: 22nd -oct25 | AFJ3: 23rd -oct25 | AFK3: 24th -oct25 | AFL3: 25th -oct25 | AFM3: 26th -oct25 | AFN3: 27th -oct25 | AFO3: 28th -oct25 | AFP3: 29th -oct25 | AFQ3: 30th -oct25 | AFR3: 31st -oct25 | AFS3: total | AFT3: 1st -nov25 | AFU3: 2nd -nov25 | AFV3: 3rd -nov25 | AFW3: 4th -nov25 | AFX3: 5th -nov25 | AFY3: 6th -nov25 | AFZ3: 7th -nov25 | AGA3: 8th -nov25 | AGB3: 9th -nov25 | AGC3: 10th -nov25 | AGD3: 11th -nov25 | AGE3: 12th -nov25 | AGF3: 13th -nov25 | AGG3: 14th -nov25 | AGH3: 15th -nov25 | AGI3: 16th -nov25 | AGJ3: 17th -nov25 | AGK3: 18th -nov25 | AGL3: 19th -nov25 | AGM3: 20th -nov25 | AGN3: 21st -nov25 | AGO3: 22nd -nov25 | AGP3: 23rd -nov25 | AGQ3: 24th -nov25 | AGR3: 25th -nov25 | AGS3: 26th -nov25 | AGT3: 27th -nov25 | AGU3: 28th -nov25 | AGV3: 29th -nov25 | AGW3: 30th -nov25 | AGX3: total | AGY3: 1st -dec25 | AGZ3: 2nd -dec25 | AHA3: 3rd -dec25 | AHB3: 4th -dec25 | AHC3: 5th -dec25 | AHD3: 6th -dec25 | AHE3: 7th -dec25 | AHF3: 8th -dec25 | AHG3: 9th -dec25 | AHH3: 10th -dec25 | AHI3: 11th -dec25 | AHJ3: 12th -dec25 | AHK3: 13th -dec25 | AHL3: 14th -dec25 | AHM3: 15th -dec25 | AHN3: 16th -dec25 | AHO3: 17th -dec25 | AHP3: 18th -dec25 | AHQ3: 19th -dec25 | AHR3: 20th -dec25 | AHS3: 21st -dec25 | AHT3: 22nd -dec25 | AHU3: 23rd -dec25 | AHV3: 24th -dec25 | AHW3: 25th -dec25 | AHX3: 26th -dec25 | AHY3: 27th -dec25 | AHZ3: 28th -dec25 | AIA3: 29th -dec25 | AIB3: 30th -dec25 | AIC3: 31st -dec25 | AID3: total | AIE3: 1st -jan26 | AIF3: 2nd -jan26 | AIG3: 3rd -jan26 | AIH3: 4th -jan26 | AII3: 5th -jan26 | AIJ3: 6th -jan26 | AIK3: 7th -jan26 | AIL3: 8th -jan26 | AIM3: 9th -jan26 | AIN3: 10th -jan26 | AIO3: 11th -jan26 | AIP3: 12th -jan26 | AIQ3: 13th -jan26 | AIR3: 14th -jan26 | AIS3: 15th -jan26 | AIT3: 16th -jan26 | AIU3: 17th -jan26 | AIV3: 18th -jan26 | AIW3: 19th -jan26 | AIX3: 20th -jan26 | AIY3: 21st -jan26 | AIZ3: 22nd -jan26 | AJA3: 23rd -jan26 | AJB3: 24th -jan26 | AJC3: 25th -jan26 | AJD3: 26th -jan26 | AJE3: 27th -jan26 | AJF3: 28th -jan26 | AJG3: 29th -jan26 | AJH3: 30th -jan26 | AJI3: 31st -jan26 | AJJ3: total | AJK3: 1st -feb2026 | AJL3: 2nd -feb2026 | AJM3: 3rd -feb2026 | AJN3: 4th -feb2026 | AJO3: 5th -feb2026 | AJP3: 6th -feb2026 | AJQ3: 7th -feb2026 | AJR3: 8th -feb2026 | AJS3: 9th -feb2026 | AJT3: 10th -feb2026 | AJU3: 11th -feb2026 | AJV3: 12th -feb2026 | AJW3: 13th -feb2026 | AJX3: 14th -feb2026 | AJY3: 15th -feb2026 | AJZ3: 16th -feb2026 | AKA3: 17th -feb2026 | AKB3: 18th -feb2026 | AKC3: 19th -feb2026 | AKD3: 20th -feb2026 | AKE3: 21st -feb2026 | AKF3: 22nd -feb2026 | AKG3: 23rd -feb2026 | AKH3: 24th -feb2026 | AKI3: 25th -feb2026 | AKJ3: 26th -feb2026 | AKK3: 27th -feb2026 | AKL3: 28th -feb2026 | AKM3: total | AKN3: 1st -mar2026 | AKO3: 2nd -mar2026 | AKP3: 3rd -mar2026 | AKQ3: 4th -mar2026 | AKR3: 5th -mar2026 | AKS3: 6th -mar2026 | AKT3: 7th -mar2026 | AKU3: 8th -mar2026 | AKV3: 9th -mar2026 | AKW3: 10th -mar2026 | AKX3: 11th -mar2026 | AKY3: 12th -mar2026 | AKZ3: 13th -mar2026 | ALA3: 14th -mar2026 | ALB3: 15th -mar2026 | ALC3: 16th -mar2026 | ALD3: 17th -mar2026 | ALE3: 18th -mar2026 | ALF3: 19th -mar2026 | ALG3: 20th -mar2026 | ALH3: 21st -mar2026 | ALI3: 22nd -mar2026 | ALJ3: 23rd -mar2026 | ALK3: 24th -mar2026 | ALL3: 25th -mar2026 | ALM3: 26th -mar2026 | ALN3: 27th -mar2026 | ALO3: 28th -mar2026 | ALP3: 29th -mar2026 | ALQ3: 30th -mar2026 | ALR3: 31st -mar2026 | ALS3: total | ALT3: 1st apr2026 | ALU3: 2nd apr2026 | ALV3: 3rd apr2026 | ALW3: 4th apr2026 | ALX3: 5th apr2026 | ALY3: 6th apr2026 | ALZ3: 7th apr2026 | AMA3: 8th apr2026 | AMB3: 9th apr2026 | AMC3: 10th apr2026 | AMD3: 11th apr2026 | AME3: 12th apr2026 | AMF3: 13th apr2026 | AMG3: 14th apr2026 | AMH3: 15th apr2026 | AMI3: 16th apr2026 | AMJ3: 17th apr2026 | AMK3: 18th apr2026 | AML3: 19th apr2026 | AMM3: 20th apr2026 | AMN3: 21st apr2026 | AMO3: 22nd apr2026 | AMP3: 23rd apr2026 | AMQ3: 24th apr2026 | AMR3: 25th apr2026 | AMS3: 26th apr2026 | AMT3: 27th apr2026 | AMU3: 28th apr2026 | AMV3: 29th apr2026 | AMW3: 30th apr2026 | AMX3: total | AMY3: 1st -may2026 | AMZ3: 2nd -may2026 | ANA3: 3rd -may2026 | ANB3: 4th -may2026 | ANC3: 5th -may2026 | AND3: 6th -may2026 | ANE3: 7th -may2026 | ANF3: 8th -may2026 | ANG3: 9th -may2026 | ANH3: 10th -may2026 | ANI3: 11th -may2026 | ANJ3: 12th -may2026 | ANK3: 13th -may2026 | ANL3: 14th -may2026 | ANM3: 15th -may2026 | ANN3: 16th -may2026 | ANO3: 17th -may2026 | ANP3: 18th -may2026 | ANQ3: 19th -may2026 | ANR3: 20th -may2026 | ANS3: 21st -may2026 | ANT3: 22nd -may2026 | ANU3: 23rd -may2026 | ANV3: 24th -may2026 | ANW3: 25th -may2026 | ANX3: 26th -may2026 | ANY3: 27th -may2026 | ANZ3: 28th -may2026 | AOA3: 29th -may2026 | AOB3: 30th -may2026 | AOC3: 10th -June2026 | AOD3: 26th -August2026
A4: MOMOPAY | B4: 1656008 | C4: 1896485 | D4: 1900500 | E4: 1307000 | F4: 1320600 | G4: 1245000 | H4: 1337725 | I4: 931700 | J4: 1315000 | K4: 1250500 | L4: 911563 | M4: 1656000 | N4: 842000 | O4: 667000 | P4: 1099000 | Q4: 802000 | R4: 1051000 | S4: 1177000 | T4: 766000 | U4: 610500 | V4: 2100000 | W4: 1108000 | X4: 2044000 | Y4: 2241654 | Z4: 1168000 | AA4: 1201200 | AB4: 771400 | AC4: 645000 | AD4: 491000 | AE4: 731000 | AF4: 1242000 | AG4: =SUM(B4:AF4) | AH4: 608500 | AI4: 834000 | AJ4: 1216886 | AK4: 2198000 | AL4: 1906595 | AM4: 1435300 | AN4: 1208000 | AO4: 2029000 | AP4: 1333600 | AQ4: 1128600 | AR4: 1288100 | AS4: 671000 | AT4: 869000 | AU4: 1012400 | AV4: 1722800 | AW4: 1033000 | AX4: 480000 | AY4: 1244000 | AZ4: 2092000 | BA4: 692000 | BB4: 1152500 | BC4: 1122300 | BD4: 1436500 | BE4: 1322100 | BF4: 1458000 | BG4: 854800 | BH4: 782000 | BI4: 684560 | BJ4: 1953463 | BK4: 1323600 | BL4: =SUM(AH4:BK4) | BM4: 1047000 | BN4: 1627000 | BO4: 1751000 | BP4: 1141000 | BQ4: 511000 | BR4: 1372312 | BS4: 1370000 | BT4: 158000 | BU4: 974700 | BV4: 951750 | BW4: 832000 | BX4: 973000 | BY4: 1484500 | BZ4: 2322000 | CA4: 1078000 | CB4: 1190000 | CC4: 847000 | CD4: 383000 | CE4: 1761170 | CF4: 723000 | CG4: 1178980 | CH4: 1037000 | CI4: 766500 | CJ4: 1736000 | CK4: 917000 | CL4: 1370000 | CM4: 1496000 | CN4: 1106000 | CO4: 1061552 | CP4: 1350421 | CQ4: 803000 | CR4: =SUM(BM4:CQ4) | CS4: 2575000 | CT4: 1032512 | CU4: 1549453 | CV4: 1163078 | CW4: 1572000 | CX4: 1357500 | CY4: 1145000 | CZ4: 711000 | DA4: 630000 | DB4: 1686000 | DC4: 842000 | DD4: 565969 | DE4: 1019000 | DF4: 1122842 | DG4: 1012000 | DH4: 773000 | DI4: 1700200 | DJ4: 1580000 | DK4: 684000 | DL4: 1780218 | DM4: 1258000 | DN4: 1173082 | DO4: 1887050 | DP4: 1415000 | DQ4: 2460200 | DR4: 1009258 | DS4: 2444200 | DT4: 1119653 | DU4: 1084650 | DV4: 1015000 | DW4: =SUM(CS4:DV4) | DX4: 894200 | DY4: 1658286 | DZ4: 708900 | EA4: 610000 | EB4: 1304500 | EC4: 1055000 | ED4: 811000 | EE4: 1426100 | EF4: 1220000 | EG4: 1530000 | EH4: 1299000 | EI4: 1527610 | EJ4: 1136000 | EK4: 850000 | EL4: 1403011 | EM4: 1591859 | EN4: 1323950 | EO4: 2499000 | EP4: 1147000 | EQ4: 632400 | ER4: 1138000 | ES4: 1527865 | ET4: 1924000 | EU4: 1501128 | EV4: 1240000 | EW4: 1299000 | EX4: 851000 | EY4: 1338078 | EZ4: 1748500 | FA4: 1992021 | FB4: 1585000 | FC4: =SUM(DX4:FB4) | FD4: 1823895 | FE4: 1199000 | FF4: 1462000 | FG4: 600000 | FH4: 445000 | FI4: 733000 | FJ4: 1637000 | FK4: 1143500 | FL4: 967000 | FM4: 1801689 | FN4: 1132600 | FO4: 949000 | FP4: 1347000 | FQ4: 2005000 | FR4: 1237000 | FS4: 902000 | FT4: 1289000 | FU4: 1318000 | FV4: 665000 | FW4: 1365500 | FX4: 1156979 | FY4: 895000 | FZ4: 1785682 | GA4: 719000 | GB4: 1006000 | GC4: 1835092 | GD4: 1320000 | GE4: 2044500 | GF4: 1124000 | GG4: 736000 | GH4: 2328000 | GI4: =SUM(FD4:GH4) | GJ4: 642000 | GK4: 774000 | GL4: 1126300 | GM4: 555000 | GN4: 1010000 | GO4: 1627300 | GP4: 1329000 | GQ4: 1568000 | GR4: 1248000 | GS4: 1427000 | GT4: 986912 | GU4: 643000 | GV4: 1649922 | GW4: 706000 | GX4: 804608 | GY4: 1237000 | GZ4: 2156432 | HA4: 1381061 | HB4: 1128000 | HC4: 1363000 | HD4: 830000 | HE4: 840000 | HF4: 2185450 | HG4: 576000 | HH4: 557000 | HI4: 468000 | HJ4: 789000 | HK4: 1208817 | HL4: 426000 | HM4: =SUM(GJ4:HL4) | HN4: 880000 | HO4: 1598000 | HP4: 1206000 | HQ4: 1775232 | HR4: 1131700 | HS4: 1820000 | HT4: 2131900 | HU4: 1653900 | HV4: 713000 | HW4: 870000 | HX4: 1099000 | HY4: 1089000 | HZ4: 2110432 | IA4: 942000 | IB4: 1376000 | IC4: 1829300 | ID4: 576200 | IE4: 1260680 | IF4: 608000 | IG4: 1719836 | IH4: 677000 | II4: 1651000 | IJ4: 1404620 | IK4: 783000 | IL4: 1419000 | IM4: 1167700 | IN4: 665400 | IO4: 1703022 | IP4: 1386003 | IQ4: 508000 | IR4: 807025 | IS4: =SUM(HN4:IR4) | IT4: 223000 | IU4: 2000169 | IV4: 496000 | IW4: 785343 | IX4: 1149000 | IY4: 870000 | IZ4: 1485000 | JA4: 2238052 | JB4: 697851 | JC4: 673000 | JD4: 1672000 | JE4: 2524583 | JF4: 1073000 | JG4: 725000 | JH4: 1193000 | JI4: 837000 | JJ4: 717000 | JK4: 1095000 | JL4: 1084500 | JM4: 685000 | JN4: 1076968 | JO4: 832700 | JP4: 704000 | JQ4: 399000 | JR4: 999950 | JS4: 1296000 | JT4: 2398500 | JU4: 1230000 | JV4: 1666500 | JW4: 877000 | JX4: =SUM(IT4:JW4) | JY4: 1235700 | JZ4: 790000 | KA4: 870000 | KB4: 709000 | KC4: 1210112 | KD4: 1168000 | KE4: 1510500 | KF4: 1061750 | KG4: 1311900 | KH4: 554000 | KI4: 788000 | KJ4: 919000 | KK4: 2611400 | KL4: 878000 | KM4: 1270500 | KN4: 1827542 | KO4: 420000 | KP4: 1465000 | KQ4: 513500 | KR4: 953000 | KS4: 2302050 | KT4: 817000 | KU4: 799000 | KV4: 1117900 | KW4: 1078000 | KX4: 1481038 | KY4: 1311000 | KZ4: 1513500 | LA4: 1107250 | LB4: 540000 | LC4: 2368000 | LD4: =SUM(JY4:LC4) | LE4: 1837864 | LF4: 1156000 | LG4: 927000 | LH4: 1204000 | LI4: 1366500 | LJ4: 592500 | LK4: 1462000 | LL4: 1097931 | LM4: 790000 | LN4: 911000 | LO4: 724000 | LP4: 1050042 | LQ4: 1363000 | LR4: 1145300 | LS4: 1831000 | LT4: 1249000 | LU4: 1374000 | LV4: 1502250 | LW4: 1583500 | LX4: 1275000 | LY4: 1700014 | LZ4: 589450 | MA4: 1317000 | MB4: 546000 | MC4: 708750 | MD4: 1398198 | ME4: 697142 | MF4: 2145500 | MG4: 938500 | MH4: 960045 | MI4: =SUM(LD4:MH4) | MJ4: 1090164 | MK4: 1156500 | ML4: 593900 | MM4: 860900 | MN4: 818000 | MO4: 994000 | MP4: 801000 | MQ4: 904000 | MR4: 596000 | MS4: 1277378 | MT4: 1370468 | MU4: 1847344 | MV4: 952450 | MW4: 1058000 | MX4: 970000 | MY4: 1527000 | MZ4: 1187800 | NA4: 1215025 | NB4: 1618998 | NC4: 1332000 | ND4: 869500 | NE4: 1747960 | NF4: 721000 | NG4: 1173000 | NH4: 1137000 | NI4: 913886 | NJ4: 1064000 | NK4: 459000 | NL4: 815000 | NM4: 1519688 | NN4: 914000 | NO4: =SUM(MJ4:NN4) | NP4: 573000 | NQ4: 1917456 | NR4: 1123504 | NS4: 1260200 | NT4: 710500 | NU4: 1030000 | NV4: 985650 | NW4: 744000 | NX4: 772900 | NY4: 462000 | NZ4: 452000 | OA4: 557000 | OB4: 1035830 | OC4: 1547000 | OD4: 1918400 | OE4: 2252000 | OF4: 1551900 | OG4: 677000 | OH4: 982200 | OI4: 1115000 | OJ4: 986000 | OK4: 924000 | OL4: 342000 | OM4: 1314000 | ON4: 490000 | OO4: 1405094 | OP4: 1147003 | OQ4: 696412 | OR4: 1178398 | OS4: 1292000 | OT4: 1059000 | OU4: =SUM(NP4:OT4) | OV4: 1082000 | OW4: 1121495 | OX4: 1266980 | OY4: 770000 | OZ4: 968000 | PA4: 1111000 | PB4: 862500 | PC4: 1625000 | PD4: 788200 | PE4: 718000 | PF4: 1261000 | PG4: 1345000 | PH4: 1730538 | PI4: 892000 | PJ4: 734900 | PK4: 1055132 | PL4: 355000 | PM4: 1257500 | PN4: 1540200 | PO4: 2783148 | PP4: 812000 | PQ4: 542014 | PR4: 695000 | PS4: 724000 | PT4: 659980 | PU4: 1191000 | PV4: 799000 | PW4: 843500 | PX4: 590000 | PY4: 736000 | PZ4: =SUM(OV4:PY4) | QA4: 768000 | QB4: 320000 | QC4: 907100 | QD4: 469000 | QE4: 1572150 | QF4: 798000 | QG4: 1112000 | QH4: 578980 | QI4: 836100 | QJ4: 624000 | QK4: 857550 | QL4: 909000 | QM4: 1440902 | QN4: 1675400 | QO4: 971700 | QP4: 1343500 | QQ4: 1050850 | QR4: 1140450 | QS4: 1231500 | QT4: 380000 | QU4: 753400 | QV4: 842100 | QW4: 485000 | QX4: 402960 | QY4: 2106000 | QZ4: 1477000 | RA4: 267000 | RB4: 1260000 | RC4: 596188 | RD4: 790000 | RE4: 953500 | RF4: =SUM(QA4:RE4) | RG4: 888000 | RH4: 1097000 | RI4: 658000 | RJ4: 837017 | RK4: 809985 | RL4: 1352780 | RM4: 758000 | RN4: 1177000 | RO4: 1104000 | RP4: 646752 | RQ4: 620000 | RR4: 2178000 | RS4: 1079599 | RT4: 410000 | RU4: 458000 | RV4: 521000 | RW4: 882000 | RX4: 734000 | RY4: 934000 | RZ4: 1192000 | SA4: 837842 | SB4: 840000 | SC4: 588000 | SD4: 450000 | SE4: 1165800 | SF4: 834333 | SG4: 2060000 | SH4: 925380 | SI4: 1140000 | SJ4: 1205000 | SK4: =SUM(RG4:SJ4) | SL4: 408900 | SM4: 820000 | SN4: 1275400 | SO4: 1181500 | SP4: 1570850 | SQ4: 803500 | SR4: 1469000 | SS4: 1278802 | ST4: 1370000 | SU4: 1715128 | SV4: 1590000 | SW4: 822800 | SX4: 2290090 | SY4: 1148109 | SZ4: 956000 | TA4: 1747890 | TB4: 2034950 | TC4: 601000 | TD4: 1859222 | TE4: 1181429 | TF4: 1247000 | TG4: 3046264 | TH4: 1196000 | TI4: 572000 | TJ4: 779559 | TK4: 671000 | TL4: 1661352 | TM4: 618000 | TN4: 1313500 | TO4: 643000 | TP4: 1383000 | TQ4: =SUM(SL4:TP4) | TR4: 641000 | TS4: 847000 | TT4: 755000 | TU4: 1901000 | TV4: 1267800 | TW4: 1721000 | TX4: 840000 | TY4: 1630000 | TZ4: 902000 | UA4: 2456590 | UB4: 538000 | UC4: 1376000 | UD4: 1391700 | UE4: 1799600 | UF4: 2289000 | UG4: 1722500 | UH4: 1480000 | UI4: 1904000 | UJ4: 1559000 | UK4: 1093000 | UL4: 1025063 | UM4: 774500 | UN4: 1146000 | UO4: 1679000 | UP4: 1427000 | UQ4: 851000 | UR4: 1651000 | US4: 1429000 | UT4: 781000 | UU4: 368000 | UV4: 1191000 | UW4: =SUM(TR4:UV4) | UX4: 796000 | UY4: 866000 | UZ4: 2355260 | VA4: 905000 | VB4: 1027000 | VC4: 1294000 | VD4: 826500 | VE4: 2025000 | VF4: 226000 | VG4: 1033000 | VH4: 462000 | VI4: 950000 | VJ4: 884000 | VK4: 864000 | VL4: 1089000 | VM4: 1230520 | VN4: 562000 | VO4: 384000 | VP4: 910000 | VQ4: 1249106 | VR4: 1495000 | VS4: 1860000 | VT4: 1260500 | VU4: 1965332 | VV4: 1037000 | VW4: 1880000 | VX4: 1884000 | VY4: 1250000 | VZ4: =SUM(UX4:VY4) | WA4: 1608652 | WB4: 917000 | WC4: 911500 | WD4: 840000 | WE4: 967200 | WF4: 1130000 | WG4: 729000 | WH4: 382000 | WI4: 484000 | WJ4: 841000 | WK4: 1610000 | WL4: 511000 | WM4: 611500 | WN4: 1051000 | WO4: 1661050 | WP4: 885000 | WQ4: 104000 | WR4: 0 | WS4: 478705 | WT4: 560000 | WU4: 578000 | WV4: 1439000 | WW4: 922000 | WX4: 2004000 | WY4: 355000 | WZ4: 1618000 | XA4: 1428800 | XB4: 1293474 | XC4: 653000 | XD4: 2462000 | XE4: 1386000 | XF4: =SUM(WA4:XE4) | XG4: 1520000 | XH4: 1163890 | XI4: 2025000 | XJ4: 997000 | XK4: 1226585 | XL4: 646000 | XM4: 1453965 | XN4: 727200 | XO4: 548850 | XP4: 758000 | XQ4: 707000 | XR4: 1865954 | XS4: 745000 | XT4: 1457850 | XU4: 1290000 | XV4: 1035000 | XW4: 1092000 | XX4: 530000 | XY4: 625030 | XZ4: 350000 | YA4: 986000 | YB4: 996000 | YC4: 1942000 | YD4: 532000 | YE4: 921000 | YF4: 770000 | YG4: 686000 | YH4: 373000 | YI4: 1210266 | YJ4: 358000 | YK4: =SUM(XF4:YJ4) | YL4: 2827000 | YM4: 1098256 | YN4: 937000 | YO4: 864500 | YP4: 1315000 | YQ4: 1103000 | YR4: 1169676 | YS4: 736500 | YT4: 982000 | YU4: 1235832 | YV4: 1252000 | YW4: 840450 | YX4: 824000 | YY4: 733500 | YZ4: 1793000 | ZA4: 1392000 | ZB4: 642000 | ZC4: 881000 | ZD4: 1561000 | ZE4: 470000 | ZF4: 1294700 | ZG4: 1474750 | ZH4: 1068000 | ZI4: 1325000 | ZJ4: 806500 | ZK4: 1456719 | ZL4: 2515000 | ZM4: 1405000 | ZN4: 662500 | ZO4: 842500 | ZP4: 806000 | ZQ4: =SUM(YL4:ZP4) | ZR4: 1700000 | ZS4: 1007000 | ZT4: 1258000 | ZU4: 2037740 | ZV4: 1400000 | ZW4: 1558046 | ZX4: 1067950 | ZY4: 874500 | ZZ4: 1500000 | AAA4: 820000 | AAB4: 557000 | AAC4: 1795000 | AAD4: 1264000 | AAE4: 1283816 | AAF4: 846472 | AAG4: 862700 | AAH4: 1286000 | AAI4: 1083832 | AAJ4: 1737482 | AAK4: 1940600 | AAL4: 856880 | AAM4: 1585000 | AAN4: 1065000 | AAO4: 1299500 | AAP4: 902509 | AAQ4: 1707000 | AAR4: 1340000 | AAS4: 1388500 | AAT4: 904000 | AAU4: 1704000 | AAV4: =SUM(ZR4:AAU4) | AAW4: 989000 | AAX4: 475000 | AAY4: 878000 | AAZ4: 1711000 | ABA4: 1003500 | ABB4: 1699500 | ABC4: 540200 | ABD4: 1891997 | ABE4: 643000 | ABF4: 1083542 | ABG4: 2508235 | ABH4: 930000 | ABI4: 1800000 | ABJ4: 1536831 | ABK4: 928000 | ABL4: 655000 | ABM4: 2021000 | ABN4: 1669800 | ABO4: 1325000 | ABP4: 1076200 | ABQ4: 1162626 | ABR4: 1196500 | ABS4: 1151404 | ABT4: 952009 | ABU4: 930000 | ABV4: 1084000 | ABW4: 650000 | ABX4: 1264000 | ABY4: 838500 | ABZ4: 1313000 | ACA4: 1996500 | ACB4: =SUM(AAX4:ACA4) | ACC4: 913000 | ACD4: 2157364 | ACE4: 1061000 | ACF4: 2929500 | ACG4: 872000 | ACH4: 1941000 | ACI4: 2588547 | ACJ4: 1466250 | ACK4: 1385000 | ACL4: 540000 | ACM4: 1318000 | ACN4: 1194500 | ACO4: 916153 | ACP4: 966076 | ACQ4: 841000 | ACR4: 1688600 | ACS4: 1151000 | ACT4: 1667535 | ACU4: 819000 | ACV4: 967190 | ACW4: 710190 | ACX4: 2732000 | ACY4: 770333 | ACZ4: 1530500 | ADA4: 1464731 | ADB4: 751200 | ADC4: 815000 | ADD4: 473000 | ADE4: 939000 | ADF4: 1066000 | ADG4: 478000 | ADH4: =SUM(ACC4:ADG4) | ADI4: 1126000 | ADJ4: 1642601 | ADK4: 1538000 | ADL4: 1410746 | ADM4: 1099000 | ADN4: 1186000 | ADO4: 1107800 | ADP4: 742000 | ADQ4: 1020000 | ADR4: 920580 | ADS4: 1103095 | ADT4: 2227109 | ADU4: 962000 | ADV4: 1262000 | ADW4: 882500 | ADX4: 511000 | ADY4: 946060 | ADZ4: 1408400 | AEA4: 1323000 | AEB4: 968000 | AEC4: 1361000 | AED4: 935000 | AEE4: 1044000 | AEF4: 1372000 | AEG4: 1276000 | AEH4: 1004000 | AEI4: 1901000 | AEJ4: 992000 | AEK4: 632000 | AEL4: 1646000 | AEM4: =SUM(ADI4:AEL4) | AEN4: 935893 | AEO4: 890000 | AEP4: 1040040 | AEQ4: 2119000 | AER4: 1027103 | AES4: 944500 | AET4: 703000 | AEU4: 2110142 | AEV4: 1684900 | AEW4: 2658489 | AEX4: 1535000 | AEY4: 1361788 | AEZ4: 2107984 | AFA4: 354000 | AFB4: 657142 | AFC4: 761000 | AFD4: 730024 | AFE4: 889000 | AFF4: 849000 | AFG4: 625000 | AFH4: 1102000 | AFI4: 1283000 | AFJ4: 1236827 | AFK4: 974000 | AFL4: 1400000 | AFM4: 2008974 | AFN4: 886330 | AFO4: 415000 | AFP4: 630725 | AFQ4: 2195000 | AFR4: 1531000 | AFS4: =SUM(AEN4:AFR4) | AFT4: 599500 | AFU4: 1221000 | AFV4: 1785000 | AFW4: 515000 | AFX4: 1283490 | AFY4: 1077000 | AFZ4: 866000 | AGE4: 60000 | AGN4: 130000 | AGX4: =SUM(AFT4:AGW4) | AID4: =SUM(AGZ4:AIC4) | AJJ4: =SUM(AIF4:AJI4) | AKM4: =SUM(AJI4:AKL4) | ALS4: =SUM(AKO4:ALR4) | AMX4: =SUM(ALT4:AMW4)
A5: AIRTEL | B5: 2169300 | C5: 1204500 | D5: 2185500 | E5: 1573000 | F5: 1008600 | G5: 2899500 | H5: 1116000 | I5: 2236800 | J5: 3300500 | K5: 1593000 | L5: 1335000 | M5: 1260000 | N5: 1038000 | O5: 1021000 | P5: 1538000 | Q5: 582600 | R5: 1396000 | S5: 959000 | T5: 815000 | U5: 1463300 | V5: 1017000 | W5: 790000 | X5: 1052300 | Y5: 1261000 | Z5: 1507800 | AA5: 1014100 | AB5: 1187000 | AC5: 518000 | AD5: 2516000 | AE5: 979000 | AF5: 758000 | AG5: =SUM(B5:AF5) | AH5: 1437000 | AI5: 1046100 | AJ5: 1065000 | AK5: 1675000 | AL5: 1615462 | AM5: 604000 | AN5: 1560238 | AO5: 2003764 | AP5: 867500 | AQ5: 1468000 | AR5: 523400 | AS5: 875000 | AT5: 755900 | AU5: 780000 | AV5: 1337500 | AW5: 1193000 | AX5: 1332000 | AY5: 1432800 | AZ5: 672000 | BA5: 1271300 | BB5: 386700 | BC5: 940740 | BD5: 1522010 | BE5: 540100 | BF5: 904000 | BG5: 2004900 | BH5: 892000 | BI5: 902000 | BJ5: 732000 | BK5: 921000 | BL5: =SUM(AH5:BK5) | BM5: 293000 | BN5: 778000 | BO5: 421900 | BP5: 1368000 | BQ5: 1064560 | BR5: 1124000 | BS5: 1139000 | BT5: 1305800 | BU5: 1657500 | BV5: 828500 | BW5: 306950 | BX5: 947000 | BY5: 639000 | BZ5: 939000 | CA5: 661500 | CB5: 1073000 | CC5: 1259500 | CD5: 314000 | CE5: 860500 | CF5: 712000 | CG5: 1014754 | CH5: 601000 | CI5: 924500 | CJ5: 480000 | CK5: 1637500 | CL5: 1332000 | CM5: 1067900 | CN5: 1758000 | CO5: 507950 | CP5: 1675700 | CQ5: 922000 | CR5: =SUM(BM5:CQ5) | CS5: 1279000 | CT5: 1380000 | CU5: 1038000 | CV5: 1588010 | CW5: 622053 | CX5: 1828800 | CY5: 1008122 | CZ5: 838000 | DA5: 1369500 | DB5: 972073 | DC5: 694000 | DD5: 1175500 | DE5: 1133695 | DF5: 1438390 | DG5: 1093000 | DH5: 612100 | DI5: 2553150 | DJ5: 497100 | DK5: 969000 | DL5: 1626490 | DM5: 1000900 | DN5: 903500 | DO5: 953000 | DP5: 679000 | DQ5: 1415100 | DR5: 819500 | DS5: 981500 | DT5: 2126000 | DU5: 514000 | DV5: 1322000 | DW5: =SUM(CS5:DV5) | DX5: 1631000 | DY5: 898000 | DZ5: 352000 | EA5: 370500 | EB5: 1413000 | EC5: 724000 | ED5: 914000 | EE5: 1747780 | EF5: 1047000 | EG5: 1539400 | EH5: 1161000 | EI5: 1748000 | EJ5: 2177962 | EK5: 1605850 | EL5: 961000 | EM5: 1564000 | EN5: 684000 | EO5: 1224900 | EP5: 803000 | EQ5: 1502000 | ER5: 2153000 | ES5: 1266500 | ET5: 2187000 | EU5: 717112 | EV5: 1548038 | EW5: 1201000 | EX5: 1383205 | EY5: 1702500 | EZ5: 1892700 | FA5: 1325000 | FB5: 789540 | FC5: =SUM(DX5:FB5) | FD5: 626333 | FE5: 439000 | FF5: 532000 | FG5: 1204900 | FH5: 2003124 | FI5: 518000 | FJ5: 955000 | FK5: 789000 | FL5: 1582000 | FM5: 275000 | FN5: 1662000 | FO5: 1093044 | FP5: 974000 | FQ5: 1022000 | FR5: 1178674 | FS5: 650000 | FT5: 1880000 | FU5: 1582000 | FV5: 1813000 | FW5: 884000 | FX5: 853000 | FY5: 662000 | FZ5: 569000 | GA5: 1526170 | GB5: 1524000 | GC5: 2441200 | GD5: 947000 | GE5: 1374000 | GF5: 1462000 | GG5: 785000 | GH5: 1781000 | GI5: =SUM(FD5:GH5) | GJ5: 1640000 | GK5: 1490000 | GL5: 1449034 | GM5: 453000 | GN5: 932000 | GO5: 800000 | GP5: 1696000 | GQ5: 957000 | GR5: 1689000 | GS5: 1344500 | GT5: 1077000 | GU5: 1599000 | GV5: 1359300 | GW5: 823703 | GX5: 1075000 | GY5: 1126972 | GZ5: 967602 | HA5: 814900 | HB5: 695000 | HC5: 1540390 | HD5: 1150200 | HE5: 715000 | HF5: 991160 | HG5: 1064000 | HH5: 771000 | HI5: 834000 | HJ5: 1032000 | HK5: 1441808 | HL5: 1368946 | HM5: =SUM(GJ5:HL5) | HN5: 1175000 | HO5: 1055000 | HP5: 1062000 | HQ5: 1519000 | HR5: 1896823 | HS5: 805900 | HT5: 1278160 | HU5: 1486160 | HV5: 1685000 | HW5: 1362000 | HX5: 1367000 | HY5: 1354000 | HZ5: 610000 | IA5: 1363500 | IB5: 3145400 | IC5: 828000 | ID5: 1249650 | IE5: 882000 | IF5: 1695000 | IG5: 924000 | IH5: 470400 | II5: 1703000 | IJ5: 1364500 | IK5: 1592250 | IL5: 1259400 | IM5: 1312500 | IN5: 932700 | IO5: 2296900 | IP5: 816000 | IQ5: 1421500 | IR5: 588400 | IS5: =SUM(HN5:IR5) | IT5: 1128000 | IU5: 1561182 | IV5: 785400 | IW5: 1354000 | IX5: 1117000 | IY5: 1191500 | IZ5: 953000 | JA5: 797500 | JB5: 1702000 | JC5: 1038000 | JD5: 1434000 | JE5: 1106900 | JF5: 2077500 | JG5: 1378500 | JH5: 983000 | JI5: 1536780 | JJ5: 1079000 | JK5: 641000 | JL5: 2637636 | JM5: 1292500 | JN5: 1081000 | JO5: 2728500 | JP5: 1455080 | JQ5: 2339531 | JR5: 465000 | JS5: 1207000 | JT5: 2168000 | JU5: 811500 | JV5: 1463085 | JW5: 1701000 | JX5: =SUM(IT5:JW5) | JY5: 1371000 | JZ5: 1212900 | KA5: 1798700 | KB5: 1761460 | KC5: 1253744 | KD5: 2674320 | KE5: 3076340 | KF5: 1821680 | KG5: 2480880 | KH5: 3013300 | KI5: 2133730 | KJ5: 830000 | KK5: 2986700 | KL5: 2926900 | KM5: 1457000 | KN5: 3459050 | KO5: 2108730 | KP5: 2337500 | KQ5: 1024000 | KR5: 2445590 | KS5: 2456370 | KT5: 2496500 | KU5: 2019000 | KV5: 2412200 | KW5: 2207880 | KX5: 1173000 | KY5: 3002660 | KZ5: 3333000 | LA5: 2541000 | LB5: 5008500 | LC5: 1319950 | LD5: =SUM(JY5:LC5) | LE5: 3509660 | LF5: 1950100 | LG5: 2454000 | LH5: 2263350 | LI5: 1815450 | LJ5: 3072850 | LK5: 2489700 | LL5: 3426000 | LM5: 854000 | LN5: 2294000 | LO5: 4265268 | LP5: 1658740 | LQ5: 2202000 | LR5: 2962213 | LS5: 2793343 | LT5: 888200 | LU5: 1877900 | LV5: 2867000 | LW5: 2999209 | LX5: 2113000 | LY5: 3588000 | LZ5: 2049000 | MA5: 514000 | MB5: 3290450 | MC5: 1602350 | MD5: 2205740 | ME5: 1228000 | MF5: 3280836 | MG5: 1326000 | MH5: 2044500 | MI5: =SUM(LD5:MH5) | MJ5: 2181100 | MK5: 1937000 | ML5: 2369000 | MM5: 1965000 | MN5: 3602000 | MO5: 1638900 | MP5: 1732500 | MQ5: 3546370 | MR5: 2896501 | MS5: 1682000 | MT5: 3423000 | MU5: 3320000 | MV5: 2853000 | MW5: 1558000 | MX5: 2680100 | MY5: 2541000 | MZ5: 1547700 | NA5: 2616018 | NB5: 1513117 | NC5: 1290000 | ND5: 960320 | NE5: 1776600 | NF5: 2696000 | NG5: 1796000 | NH5: 2729300 | NI5: 3264100 | NJ5: 1277000 | NK5: 1236000 | NL5: 2005000 | NM5: 2110300 | NN5: 1924000 | NO5: =SUM(MJ5:NN5) | NP5: 2068500 | NQ5: 2502000 | NR5: 3647892 | NS5: 1743500 | NT5: 2372800 | NU5: 3323409 | NV5: 2913000 | NW5: 3078500 | NX5: 2473000 | NY5: 1880700 | NZ5: 1440904 | OA5: 1790000 | OB5: 1453000 | OC5: 2304900 | OD5: 962000 | OE5: 2684415 | OF5: 1532500 | OG5: 1156500 | OH5: 1015000 | OI5: 1457000 | OJ5: 1379300 | OK5: 1078000 | OL5: 1264500 | OM5: 1287000 | ON5: 329000 | OO5: 1526500 | OP5: 3350963 | OQ5: 889760 | OR5: 1603260 | OS5: 1257010 | OT5: 1341760 | OU5: =SUM(NP5:OT5) | OV5: 947500 | OW5: 1358900 | OX5: 2014100 | OY5: 2974000 | OZ5: 2374500 | PA5: 1228000 | PB5: 1187500 | PC5: 1214000 | PD5: 1520000 | PE5: 2447500 | PF5: 1702300 | PG5: 619500 | PH5: 2894600 | PI5: 829400 | PJ5: 1721500 | PK5: 1283000 | PL5: 712000 | PM5: 2373000 | PN5: 1161100 | PO5: 740000 | PP5: 422000 | PQ5: 1482000 | PR5: 924500 | PS5: 1501000 | PT5: 852000 | PU5: 1416714 | PV5: 868000 | PW5: 626500 | PX5: 1067675 | PY5: 1623400 | PZ5: =SUM(OV5:PY5) | QA5: 1145000 | QB5: 740000 | QC5: 1339000 | QD5: 1784600 | QE5: 1214000 | QF5: 2010100 | QG5: 1409000 | QH5: 1523000 | QI5: 1283750 | QJ5: 865250 | QK5: 1958900 | QL5: 1147000 | QM5: 1577500 | QN5: 1405000 | QO5: 2060000 | QP5: 636000 | QQ5: 1711000 | QR5: 1315000 | QS5: 4169700 | QT5: 853500 | QU5: 831500 | QV5: 1104500 | QW5: 1050485 | QX5: 939985 | QY5: 1774000 | QZ5: 596000 | RA5: 1093500 | RB5: 1490750 | RC5: 2072300 | RD5: 1685000 | RE5: 2108908 | RF5: =SUM(QA5:RE5) | RG5: 1267000 | RH5: 626648 | RI5: 1975000 | RJ5: 1515380 | RK5: 972785 | RL5: 1026000 | RM5: 1492000 | RN5: 844000 | RO5: 1084000 | RP5: 993500 | RQ5: 1229000 | RR5: 1433285 | RS5: 1174304 | RT5: 1170400 | RU5: 1685500 | RV5: 1750500 | RW5: 1255500 | RX5: 2286285 | RY5: 2582300 | RZ5: 1316500 | SA5: 710500 | SB5: 1230500 | SC5: 1655500 | SD5: 2170740 | SE5: 2753500 | SF5: 1166755 | SG5: 1054800 | SH5: 1045000 | SI5: 1615900 | SJ5: 1176049 | SK5: =SUM(RG5:SJ5) | SL5: 861500 | SM5: 1074355 | SN5: 1597000 | SO5: 1542000 | SP5: 1968868 | SQ5: 1706000 | SR5: 1294000 | SS5: 678000 | ST5: 2844355 | SU5: 1632350 | SV5: 854000 | SW5: 1259000 | SX5: 2575000 | SY5: 829000 | SZ5: 2259840 | TA5: 1790355 | TB5: 1891560 | TC5: 2340000 | TD5: 2092230 | TE5: 1170000 | TF5: 1300500 | TG5: 1575033 | TH5: 982355 | TI5: 2000000 | TJ5: 1085000 | TK5: 947000 | TL5: 1260500 | TM5: 1830000 | TN5: 1073000 | TO5: 708000 | TP5: 1759910 | TQ5: =SUM(SL5:TP5) | TR5: 353474 | TS5: 1026000 | TT5: 1354000 | TU5: 707560 | TV5: 1308000 | TW5: 845355 | TX5: 776000 | TY5: 1414500 | TZ5: 1806000 | UA5: 2354000 | UB5: 1835000 | UC5: 747000 | UD5: 960000 | UE5: 1686061 | UF5: 1732500 | UG5: 1172000 | UH5: 1116700 | UI5: 1748000 | UJ5: 950000 | UK5: 1577355 | UL5: 1413000 | UM5: 1553000 | UN5: 1473000 | UO5: 1733058 | UP5: 1290800 | UQ5: 1771500 | UR5: 912655 | US5: 1415000 | UT5: 598000 | UU5: 975000 | UV5: 1190241 | UW5: =SUM(TR5:UV5) | UX5: 2338275 | UY5: 1534000 | UZ5: 774000 | VA5: 3229000 | VB5: 1496900 | VC5: 1212000 | VD5: 446900 | VE5: 1182000 | VF5: 1342000 | VG5: 1559500 | VH5: 2429000 | VI5: 1141500 | VJ5: 1779852 | VK5: 1360350 | VL5: 1431900 | VM5: 2328000 | VN5: 694384 | VO5: 1181490 | VP5: 779970 | VQ5: 2053000 | VR5: 1687000 | VS5: 1416000 | VT5: 998096 | VU5: 979000 | VV5: 2288200 | VW5: 1209000 | VX5: 1479710 | VY5: 1340000 | VZ5: =SUM(UX5:VY5) | WA5: 1793000 | WB5: 767800 | WC5: 1308417 | WD5: 1200000 | WE5: 1136000 | WF5: 879000 | WG5: 1398000 | WH5: 1195710 | WI5: 882000 | WJ5: 1475000 | WK5: 1826000 | WL5: 957500 | WM5: 1655000 | WN5: 545000 | WO5: 1730000 | WP5: 966700 | WQ5: 998000 | WR5: 0 | WS5: 773500 | WT5: 1114962 | WU5: 1188000 | WV5: 2092000 | WW5: 1486000 | WX5: 1547000 | WY5: 2942000 | WZ5: 837000 | XA5: 2102000 | XB5: 1461000 | XC5: 1935500 | XD5: 907000 | XE5: 2456059 | XF5: =SUM(WA5:XE5) | XG5: 1335500 | XH5: 1223000 | XI5: 1796400 | XJ5: 1669620 | XK5: 987000 | XL5: 2099520 | XM5: 1922587 | XN5: 1718200 | XO5: 1281540 | XP5: 1406800 | XQ5: 3226734 | XR5: 1601743 | XS5: 1498000 | XT5: 1722000 | XU5: 2090826 | XV5: 1640550 | XW5: 1180000 | XX5: 2219900 | XY5: 2042700 | XZ5: 1665000 | YA5: 1651000 | YB5: 847500 | YC5: 946000 | YD5: 1965000 | YE5: 3158207 | YF5: 1514000 | YG5: 1588000 | YH5: 1262000 | YI5: 677500 | YJ5: 939000 | YK5: =SUM(XF5:YJ5) | YL5: 1639500 | YM5: 2209500 | YN5: 1083000 | YO5: 618600 | YP5: 1447000 | YQ5: 902000 | YR5: 820000 | YS5: 300000 | YT5: 1322222 | YU5: 1256000 | YV5: 1026000 | YW5: 1207000 | YX5: 1634100 | YY5: 1019000 | YZ5: 955000 | ZA5: 1267179 | ZB5: 1449000 | ZC5: 1049800 | ZD5: 956000 | ZE5: 1937059 | ZF5: 1925000 | ZG5: 1302000 | ZH5: 1800000 | ZI5: 1537000 | ZJ5: 1018000 | ZK5: 2519750 | ZL5: 1507000 | ZM5: 1362500 | ZN5: 2789000 | ZO5: 1091000 | ZP5: 1843000 | ZQ5: =SUM(YL5:ZP5) | ZR5: 1001000 | ZS5: 2577500 | ZT5: 1070000 | ZU5: 1873000 | ZV5: 1305000 | ZW5: 865000 | ZX5: 1109126 | ZY5: 896000 | ZZ5: 577000 | AAA5: 760000 | AAB5: 570500 | AAC5: 986000 | AAD5: 1238910 | AAE5: 1803000 | AAF5: 1769000 | AAG5: 1166331 | AAH5: 1083000 | AAI5: 1913000 | AAJ5: 1152500 | AAK5: 3011624 | AAL5: 1532000 | AAM5: 1725200 | AAN5: 1507000 | AAO5: 1281000 | AAP5: 1384450 | AAQ5: 1794000 | AAR5: 1074000 | AAS5: 2144905 | AAT5: 1223000 | AAU5: 1762500 | AAV5: =SUM(ZR5:AAU5) | AAW5: 2785500 | AAX5: 2495500 | AAY5: 690000 | AAZ5: 1472950 | ABA5: 1637000 | ABB5: 1435620 | ABC5: 522000 | ABD5: 2259300 | ABE5: 1249800 | ABF5: 784800 | ABG5: 1543000 | ABH5: 2222000 | ABI5: 2834100 | ABJ5: 2086000 | ABK5: 2130000 | ABL5: 1464423 | ABM5: 1012000 | ABN5: 2304000 | ABO5: 1219000 | ABP5: 1872000 | ABQ5: 1451756 | ABR5: 1703000 | ABS5: 1161000 | ABT5: 1376919 | ABU5: 3343700 | ABV5: 2548165 | ABW5: 1789000 | ABX5: 2167500 | ABY5: 2920555 | ABZ5: 856000 | ACA5: 1518122 | ACB5: =SUM(AAX5:ACA5) | ACC5: 880000 | ACD5: 2694000 | ACE5: 715000 | ACF5: 1902000 | ACG5: 1794000 | ACH5: 2131000 | ACI5: 1135000 | ACJ5: 1842500 | ACK5: 1679000 | ACL5: 1831500 | ACM5: 1384000 | ACN5: 1030100 | ACO5: 1275000 | ACP5: 1949636 | ACQ5: 1883000 | ACR5: 1315000 | ACS5: 1908831 | ACT5: 965000 | ACU5: 1316000 | ACV5: 1061000 | ACW5: 899500 | ACX5: 1284500 | ACY5: 1039841 | ACZ5: 1944500 | ADA5: 1203400 | ADB5: 190000 | ADC5: 1313810 | ADD5: 1376000 | ADE5: 2718047 | ADF5: 942500 | ADG5: 1488000 | ADH5: =SUM(ACC5:ADG5) | ADI5: 1329841 | ADJ5: 1307000 | ADK5: 965500 | ADL5: 1118000 | ADM5: 1168000 | ADN5: 1031500 | ADO5: 1091000 | ADP5: 1293258 | ADQ5: 2401300 | ADR5: 1708000 | ADS5: 2010800 | ADT5: 2558500 | ADU5: 1596000 | ADV5: 843095 | ADW5: 1831000 | ADX5: 1046000 | ADY5: 1386000 | ADZ5: 1149500 | AEA5: 1362500 | AEB5: 1764900 | AEC5: 1399000 | AED5: 1269500 | AEE5: 1351000 | AEF5: 775000 | AEG5: 596000 | AEH5: 1415000 | AEI5: 1336000 | AEJ5: 613500 | AEK5: 1426595 | AEL5: 3026000 | AEM5: =SUM(ADI5:AEL5) | AEN5: 1106700 | AEO5: 1305000 | AEP5: 1132000 | AEQ5: 1816506 | AER5: 1511595 | AES5: 456000 | AET5: 868000 | AEU5: 1516000 | AEV5: 2305000 | AEW5: 1115000 | AEX5: 1866609 | AEY5: 1938632 | AEZ5: 1668000 | AFA5: 2289500 | AFB5: 1227000 | AFC5: 1079000 | AFD5: 1200500 | AFE5: 1198100 | AFF5: 1668000 | AFG5: 1181000 | AFH5: 1140000 | AFI5: 1120000 | AFJ5: 1875206 | AFK5: 1968848 | AFL5: 2085000 | AFM5: 1869600 | AFN5: 979000 | AFO5: 760000 | AFP5: 1840500 | AFQ5: 2492800 | AFR5: 1472000 | AFS5: =SUM(AEN5:AFR5) | AFT5: 2164800 | AFU5: 2186435 | AFV5: 838600 | AFW5: 1976800 | AFX5: 2283800 | AFY5: 2140255 | AFZ5: 662000 | AGA5: 30000 | AGF5: 0 | AGX5: =SUM(AFT5:AGW5) | AID5: =SUM(AGZ5:AIC5) | AJJ5: =SUM(AIF5:AJI5) | AKM5: =SUM(AJI5:AKL5) | ALS5: =SUM(AKO5:ALR5) | AMC5: 10000 | AMX5: =SUM(ALT5:AMW5) | ANS5: 284000 | ANT5: 753500 | ANU5: 856000 | ANV5: 742300 | ANW5: 2482975 | ANX5: 3207095 | ANY5: 474400 | ANZ5: 1656250 | AOA5: 1653800 | AOB5: 2389033 | AOC5: 1055808 | AOD5: 1055808
A6: VISA CARD | B6: 710000 | C6: 330000 | D6: 55000 | E6: 1316400 | F6: 1692230 | G6: 1004268 | H6: 372000 | I6: 472250 | J6: 490000 | K6: 771000 | L6: 2024588 | M6: 440000 | N6: 913865 | O6: 585000 | P6: 170000 | Q6: 887317 | R6: 164000 | S6: 641000 | T6: =837500+(563500) | U6: 260000 | V6: 492000 | W6: 360000 | X6: 1266321 | Y6: 835700 | Z6: 1106385 | AA6: 488300 | AB6: 1433857 | AC6: 575000 | AD6: 623000 | AE6: 1086000 | AF6: 415000 | AG6: =SUM(B6:AF6) | AH6: 897366 | AI6: 886028 | AJ6: 830500 | AK6: 555941 | AL6: 518000 | AM6: 312000 | AN6: 494503 | AO6: 575746 | AP6: 455000 | AQ6: 634000 | AR6: 415822 | AS6: 400600 | AT6: 1052000 | AU6: 886500 | AV6: =190000+170000 | AW6: 470200 | AX6: 520000 | AY6: 426000 | AZ6: 260000 | BA6: 257000 | BB6: 465000 | BC6: 522000 | BD6: 300900 | BE6: 549042 | BF6: 425958 | BG6: 728000 | BH6: 895800 | BI6: 771833 | BJ6: 60000 | BK6: 726071 | BL6: =SUM(AH6:BK6) | BM6: 595500 | BN6: 396500 | BO6: 702558 | BP6: 310000 | BQ6: 695663 | BR6: 894000 | BS6: 366000 | BT6: 740500 | BU6: 728950 | BV6: 641000 | BW6: 600600 | BX6: 1840000 | BY6: 1052574 | BZ6: 197800 | CA6: 668000 | CB6: 418000 | CC6: 459000 | CD6: 434000 | CE6: 470565 | CF6: 820124 | CG6: 422000 | CH6: 588000 | CI6: 203500 | CJ6: 898400 | CK6: 320000 | CL6: 871900 | CM6: 445000 | CN6: 577200 | CO6: 522000 | CP6: 527000 | CQ6: 540400 | CR6: =SUM(BM6:CQ6) | CS6: 17500 | CT6: 436500 | CU6: 130000 | CV6: 315000 | CW6: 911800 | CX6: 588696 | CY6: 160500 | CZ6: 224500 | DA6: 183000 | DB6: 293000 | DC6: 235000 | DD6: 427000 | DE6: 443000 | DF6: 1057612 | DG6: 120000 | DH6: 592800 | DI6: 193000 | DJ6: 263000 | DK6: 399500 | DL6: 669370 | DN6: 180000 | DO6: 946000 | DP6: 140000 | DQ6: 649500 | DR6: 160000 | DS6: 30000 | DT6: 0 | DU6: 100000 | DV6: 182000 | DW6: =SUM(CS6:DV6) | DX6: 899800 | DY6: 123500 | DZ6: 237000 | EA6: 571000 | EB6: 46000 | EC6: 110000 | ED6: 9500 | EE6: 56000 | EF6: 999600 | EG6: 510900 | EH6: 892013 | EI6: 785000 | EJ6: 470000 | EK6: 254000 | EL6: 1184911 | EM6: 430300 | EN6: 1065500 | EO6: 689000 | EP6: 668849 | EQ6: 689800 | ER6: 1842300 | ES6: 643800 | ET6: 311042 | EU6: 823000 | EV6: 1224751 | EW6: 10000 | EX6: 190500 | EY6: 1169700 | EZ6: 933150 | FA6: 451000 | FB6: 96000 | FC6: =SUM(DX6:FB6) | FD6: 498300 | FE6: 444600 | FF6: 150000 | FG6: 710061 | FH6: 130000 | FI6: 233500 | FJ6: 247200 | FK6: 737988 | FL6: 415000 | FM6: 110000 | FO6: 535900 | FP6: 849633 | FQ6: 313400 | FR6: 811443 | FS6: 309500 | FT6: 752500 | FU6: 286500 | FV6: 205000 | FW6: 416000 | FX6: 1159300 | FY6: 1955500 | GA6: 394372 | GB6: 565000 | GC6: 716900 | GD6: 476500 | GE6: 560000 | GF6: 516929 | GG6: 410000 | GH6: 404500 | GI6: =SUM(FD6:GH6) | GJ6: 30000 | GK6: 421000 | GL6: 674553 | GM6: 546964 | GN6: 576500 | GO6: 1559030 | GP6: 100000 | GQ6: 655500 | GR6: 229000 | GS6: 202000 | GT6: 135500 | GU6: 687592 | GV6: 0 | GW6: 80000 | GX6: 495000 | GY6: 200000 | GZ6: 710000 | HA6: 150000 | HB6: 173000 | HC6: 60000 | HD6: 512000 | HE6: 0 | HF6: 1030000 | HG6: 700000 | HH6: 482000 | HI6: 405500 | HJ6: 345000 | HK6: 540500 | HL6: 215500 | HM6: =SUM(GJ6:HL6) | HN6: 595236 | HO6: 1229495 | HP6: 241000 | HQ6: 935000 | HR6: 427500 | HS6: 485900 | HT6: 508856 | HU6: 270000 | HV6: 82500 | HW6: 150000 | HY6: 0 | IA6: 0 | ID6: 217000 | IE6: 181000 | IF6: 147400 | IH6: 500000 | II6: 180000 | IJ6: 1014861 | IK6: 39000 | IL6: 1102000 | IM6: 225500 | IN6: 289200 | IO6: 50000 | IS6: =SUM(HN6:IR6) | IX6: 195200 | IY6: 316100 | IZ6: 830000 | JA6: 212500 | JB6: 131800 | JC6: 672710 | JD6: 512051 | JE6: 0 | JF6: 456000 | JG6: 270000 | JH6: 150000 | JI6: 311000 | JJ6: 15400 | JK6: 446400 | JL6: 30000 | JM6: 130000 | JN6: 270000 | JO6: 425000 | JP6: 230000 | JQ6: 250000 | JR6: 350000 | JS6: 105000 | JT6: 1214791 | JU6: 1471648 | JV6: 622165 | JW6: 130000 | JX6: =SUM(IT6:JW6) | JY6: 755000 | JZ6: 373000 | KA6: 390000 | KB6: 870656 | KC6: 570000 | KD6: 70000 | KE6: 485000 | KF6: 360000 | KG6: 450000 | KH6: 799117 | KI6: 930000 | KJ6: 600000 | KK6: 90000 | KL6: 993800 | KN6: 687500 | KO6: 389146 | KP6: 1128300 | KQ6: 1103556 | KR6: 300000 | KS6: 966000 | KT6: 330000 | KU6: 497000 | KV6: 220000 | KW6: 360000 | KX6: 678200 | KY6: 731000 | KZ6: 50000 | LA6: 399500 | LB6: 414000 | LC6: 1090000 | LD6: =SUM(JY6:LC6) | LE6: 921600 | LF6: 365000 | LG6: 554000 | LH6: 1308465 | LI6: 285000 | LJ6: 122000 | LK6: 1396128 | LL6: 494500 | LM6: 451500 | LN6: 740000 | LO6: 880000 | LP6: 852000 | LQ6: 140000 | LR6: 248000 | LS6: 330000 | LT6: 607000 | LU6: 500785 | LV6: 1053000 | LW6: 876000 | LX6: 577000 | LY6: 1220000 | LZ6: 836000 | MA6: 472994 | MB6: 570900 | MC6: 692700 | MD6: 585877 | ME6: 154000 | MF6: 250000 | MG6: 441400 | MH6: 360000 | MI6: =SUM(LD6:MH6) | MJ6: 1381874 | MK6: 901000 | ML6: 355000 | MM6: 245000 | MN6: 612000 | MO6: 630967 | MP6: 875000 | MQ6: 218000 | MR6: 195000 | MS6: 416500 | MT6: 660000 | MU6: 395000 | MV6: 1202153 | MW6: 308000 | MX6: 245000 | MY6: 428000 | MZ6: 310000 | NA6: 375000 | NB6: 435500 | NC6: 220000 | ND6: 1334000 | NE6: 450000 | NF6: 683156 | NG6: 200000 | NH6: 295032 | NI6: 679152 | NJ6: 865604 | NK6: 688000 | NL6: 711000 | NM6: 305000 | NN6: 601000 | NO6: =SUM(MJ6:NN6) | NP6: 597000 | NQ6: 385000 | NR6: 872000 | NS6: 1037332 | NT6: 950000 | NU6: 420000 | NV6: 107000 | NW6: 558000 | NX6: 1105956 | NY6: 1068000 | NZ6: 566616 | OA6: 1150000 | OB6: 33500 | OC6: 70000 | OD6: 165500 | OE6: 444400 | OF6: 1043024 | OG6: 196000 | OH6: 340000 | OI6: 100000 | OJ6: 439823 | OK6: 440000 | OL6: 342000 | OM6: 319000 | ON6: 105000 | OO6: 575000 | OP6: 240000 | OQ6: 71900 | OR6: 625000 | OS6: 593800 | OT6: 776277 | OU6: =SUM(NP6:OT6) | OV6: 648791 | OW6: 570700 | OX6: 533500 | OY6: 520000 | OZ6: 515000 | PA6: 1129576 | PB6: 170000 | PC6: 206000 | PD6: 750000 | PE6: 215000 | PF6: 252415 | PG6: 206900 | PH6: 497500 | PI6: 125000 | PJ6: 463000 | PK6: 132000 | PL6: 831000 | PM6: 473162 | PN6: 57000 | PO6: 331500 | PP6: 320000 | PQ6: 281750 | PR6: 389000 | PS6: 476900 | PT6: 50000 | PU6: 275000 | PV6: 385900 | PW6: 714596 | PX6: 738800 | PY6: 399000 | PZ6: =SUM(OV6:PY6) | QA6: 240000 | QB6: 450000 | QC6: 350000 | QD6: 562950 | QE6: 335000 | QF6: 235000 | QG6: 760000 | QH6: 488000 | QI6: 200000 | QJ6: 300000 | QK6: 674909 | QL6: 282000 | QM6: 465700 | QN6: 470000 | QO6: 325000 | QP6: 330000 | QQ6: 271000 | QR6: 637550 | QS6: 343900 | QT6: 484000 | QU6: 356000 | QV6: 314000 | QW6: 430000 | QX6: 610000 | QY6: 400000 | QZ6: 410000 | RA6: 266000 | RB6: 480000 | RC6: 799500 | RD6: 170000 | RE6: 220000 | RF6: =SUM(QA6:RE6) | RG6: 824890 | RH6: 70000 | RI6: 45000 | RJ6: 665000 | RK6: 0 | RL6: 235000 | RM6: 126000 | RN6: 207000 | RO6: 25000 | RP6: 276000 | RQ6: 638711 | RR6: 150000 | RS6: 1243466 | RT6: 200000 | RU6: 380000 | RV6: 310000 | RW6: 625742 | RX6: 881400 | RY6: 1161000 | RZ6: 200000 | SA6: 55000 | SB6: 758802 | SC6: 79500 | SD6: 176000 | SE6: 767000 | SF6: 424500 | SG6: 275500 | SH6: 313000 | SI6: 360000 | SJ6: 552496 | SK6: =SUM(RG6:SJ6) | SL6: 320000 | SM6: 510000 | SN6: 230000 | SO6: 325000 | SP6: 120000 | SQ6: 385000 | SR6: 80000 | SS6: 210000 | ST6: 697150 | SU6: 270000 | SV6: 1065000 | SW6: 315000 | SX6: 723000 | SY6: 219000 | SZ6: 110000 | TA6: 172000 | TB6: 148000 | TC6: 289000 | TD6: 546663 | TE6: 270000 | TF6: 450000 | TG6: 285000 | TH6: 320000 | TI6: 194500 | TJ6: 612000 | TK6: 330000 | TL6: 961400 | TM6: 932500 | TN6: 253000 | TO6: 461500 | TP6: 280000 | TQ6: =SUM(SL6:TP6) | TR6: 1005085 | TS6: 191000 | TT6: 45500 | TU6: 450000 | TV6: 324500 | TW6: 190000 | TX6: 574371 | TY6: 670978 | TZ6: 330000 | UA6: 400000 | UB6: 448900 | UC6: 170000 | UD6: 120000 | UE6: 486011 | UF6: 250000 | UG6: 448864 | UH6: 625000 | UI6: 743314 | UJ6: 350000 | UK6: 725000 | UL6: 315524 | UM6: 700000 | UN6: 550000 | UO6: 611000 | UP6: 525000 | UQ6: 1040000 | UR6: 380000 | US6: 187000 | UT6: 112000 | UU6: 120000 | UV6: 410000 | UW6: =SUM(TR6:UV6) | UX6: 228000 | UY6: 520000 | UZ6: 310000 | VA6: 167000 | VB6: 263766 | VC6: 603000 | VD6: 470000 | VE6: 390500 | VF6: 288500 | VG6: 211000 | VH6: 858500 | VI6: 430000 | VJ6: 9500 | VK6: 433500 | VL6: 195000 | VM6: 177000 | VN6: 779200 | VO6: 301500 | VP6: 120000 | VQ6: 20000 | VR6: 378500 | VS6: 175300 | VT6: 245000 | VU6: 221000 | VV6: 159101 | VW6: 338500 | VX6: 354000 | VY6: 354000 | VZ6: =SUM(UX6:VY6) | WA6: 143000 | WB6: 563955 | WC6: 300000 | WD6: 1452456 | WE6: 173000 | WF6: 214000 | WG6: 561000 | WH6: 400000 | WI6: 384000 | WJ6: 260000 | WK6: 150000 | WL6: 526000 | WM6: 240000 | WN6: 615000 | WO6: 500000 | WP6: 239000 | WQ6: 10000 | WR6: 1078795 | WS6: 250000 | WT6: 50000 | WU6: 205000 | WV6: 522036 | WW6: 450000 | WX6: 316000 | WY6: 405000 | WZ6: 230000 | XA6: 1320000 | XB6: 658863 | XC6: 476441 | XD6: 182000 | XE6: 140000 | XF6: =SUM(WA6:XE6) | XG6: 395000 | XH6: 122000 | XI6: 500000 | XJ6: 232000 | XK6: 160000 | XL6: 840424 | XM6: 461462 | XN6: 0 | XO6: 88000 | XP6: 145000 | XQ6: 410000 | XR6: 596310 | XS6: 307578 | XT6: 80000 | XU6: 496000 | XV6: 150000 | XW6: 470000 | XX6: 255000 | XY6: 400000 | XZ6: 303786 | YA6: 615000 | YB6: 50000 | YC6: 160000 | YD6: 713728 | YE6: 445000 | YF6: 1309036 | YG6: 618000 | YH6: 20000 | YI6: 40000 | YJ6: 550000 | YK6: =SUM(XF6:YJ6) | YL6: 477000 | YM6: 584320 | YN6: 343000 | YO6: 275000 | YP6: 120000 | YQ6: 417000 | YR6: 410000 | YS6: 435000 | YT6: 150000 | YU6: 565000 | YV6: 33000 | YW6: 212000 | YX6: 520000 | YY6: 579850 | YZ6: 222500 | ZA6: 100000 | ZB6: 543990 | ZC6: 50000 | ZD6: 180000 | ZE6: 50000 | ZF6: 200000 | ZG6: 479500 | ZH6: 220000 | ZI6: 514186 | ZJ6: 201500 | ZK6: 265000 | ZL6: 410000 | ZM6: 110000 | ZN6: 360000 | ZO6: 173000 | ZP6: 80000 | ZQ6: =SUM(YL6:ZP6) | ZR6: 230000 | ZS6: 195000 | ZT6: 185000 | ZU6: 135000 | ZV6: 308449 | ZW6: 1201950 | ZX6: 120000 | ZY6: 405500 | ZZ6: 40000 | AAA6: 80000 | AAB6: 220000 | AAC6: 405000 | AAD6: 395000 | AAE6: 1682500 | AAF6: 638146 | AAG6: 421822 | AAH6: 348000 | AAI6: 217000 | AAJ6: 200000 | AAK6: 220000 | AAL6: 838500 | AAM6: 513500 | AAN6: 260000 | AAO6: 0 | AAP6: 1171000 | AAQ6: 847000 | AAR6: 729260 | AAS6: 823737 | AAT6: 488595 | AAU6: 120000 | AAV6: =SUM(ZR6:AAU6) | AAW6: 791000 | AAX6: 420500 | AAY6: 82000 | AAZ6: 632242 | ABA6: 417000 | ABB6: 217500 | ABC6: 286000 | ABD6: 477000 | ABE6: 60000 | ABF6: 262600 | ABG6: 150000 | ABH6: 127000 | ABI6: 274400 | ABJ6: 129000 | ABK6: 20000 | ABL6: 335129 | ABM6: 98500 | ABN6: 36000 | ABO6: 491000 | ABP6: 388000 | ABQ6: 365000 | ABS6: 260000 | ABT6: 100000 | ABU6: 498000 | ABV6: 100000 | ABW6: 1117000 | ABX6: 2250000 | ABY6: 10000 | ABZ6: 100000 | ACA6: 127000 | ACB6: =SUM(AAX6:ACA6) | ACC6: 277500 | ACD6: 320000 | ACE6: 810000 | ACF6: 645000 | ACG6: 180000 | ACH6: 271000 | ACJ6: 644642 | ACK6: 126000 | ACL6: 315169 | ACM6: 950000 | ACN6: 470000 | ACO6: 624378 | ACP6: 270000 | ACQ6: 491203 | ACR6: 643122 | ACS6: 345912 | ACT6: 929000 | ACU6: 28000 | ACV6: 163000 | ACW6: 850000 | ACX6: 210500 | ACY6: 586499 | ACZ6: 200000 | ADA6: 0 | ADB6: 1488050 | ADC6: 93000 | ADD6: 504828 | ADE6: 390000 | ADF6: 760000 | ADG6: 509270 | ADH6: =SUM(ACC6:ADG6) | ADI6: 60000 | ADJ6: 427501 | ADK6: 613000 | ADL6: 220095 | ADM6: 204000 | ADN6: 450000 | ADO6: 235000 | ADP6: 210000 | ADQ6: 166000 | ADR6: 848000 | ADS6: 360000 | ADT6: 456000 | ADU6: 411000 | ADV6: 70000 | ADW6: 402541 | ADX6: 631281 | ADY6: 350000 | ADZ6: 250000 | AEA6: 60000 | AEB6: 270000 | AEC6: 290000 | AED6: 270000 | AEE6: 100000 | AEF6: 50000 | AEG6: 150000 | AEH6: 455000 | AEI6: 448416 | AEJ6: 450000 | AEK6: 613048 | AEL6: 235000 | AEM6: =SUM(ADI6:AEL6) | AEN6: 90000 | AEP6: 50000 | AEQ6: 230000 | AER6: 150000 | AES6: 550000 | AET6: 100000 | AEU6: 157000 | AEV6: 1172538 | AEW6: 20000 | AEX6: 165000 | AEZ6: 130000 | AFA6: 327510 | AFB6: 410000 | AFC6: 180000 | AFD6: 210000 | AFE6: 694787 | AFF6: 120000 | AFG6: 390000 | AFH6: 220000 | AFI6: 535892 | AFJ6: 20000 | AFK6: 613558 | AFL6: 465000 | AFM6: 1141975 | AFN6: 252000 | AFO6: 300000 | AFP6: 550000 | AFQ6: 322000 | AFR6: 745000 | AFS6: =SUM(AEN6:AFR6) | AFT6: 30000 | AFU6: 435000 | AFV6: 142000 | AFW6: 240000 | AFX6: 752000 | AFY6: 320000 | AFZ6: 50000 | AGA6: 145000 | AGB6: 253700 | AGC6: 484490 | AGD6: 630000 | AGE6: 425000 | AGF6: 500000 | AGG6: 357227 | AGH6: 510000 | AGI6: 135490 | AGJ6: 864908 | AGK6: 131000 | AGL6: 30000 | AGM6: 110000 | AGN6: 753000 | AGO6: 210000 | AGP6: 379000 | AGQ6: 310000 | AGR6: 824500 | AGS6: 100000 | AGT6: 203790 | AGU6: 412000 | AGV6: 545000 | AGW6: 550000 | AGX6: =SUM(AFT6:AGW6) | AGY6: 630000 | AHA6: 150000 | AHC6: 390000 | AHD6: 634976 | AHE6: 353000 | AHF6: 0 | AHG6: 225000 | AHH6: 1392000 | AHI6: 555700 | AHJ6: 150000 | AHK6: 235000 | AHL6: 930000 | AHM6: 400000 | AHN6: 100000 | AHO6: 250000 | AHP6: 152945 | AHQ6: 775000 | AHR6: 555000 | AHS6: 829235 | AHT6: 500000 | AHU6: 120000 | AHV6: 299490 | AHW6: 664669 | AHX6: 761797 | AHY6: 245000 | AHZ6: 321109 | AIA6: 235000 | AIB6: 430000 | AIC6: 170000 | AID6: =SUM(AGY6:AIC6) | AIE6: 350000 | AIF6: 650000 | AIG6: 270000 | AIH6: 459490 | AII6: 865000 | AIJ6: 440989 | AIK6: 231000 | AIL6: 170000 | AIM6: 880000 | AIN6: 886505 | AIO6: 406093 | AIP6: 402012 | AIQ6: 160000 | AIR6: 150000 | AIS6: 55000 | AIT6: 265000 | AIU6: 130000 | AIV6: 189000 | AIW6: 395000 | AIY6: 150000 | AIZ6: 555500 | AJA6: 210000 | AJB6: 508000 | AJC6: 330000 | AJD6: 170000 | AJE6: 430000 | AJF6: 200000 | AJG6: 410000 | AJH6: 800000 | AJI6: 273000 | AJJ6: =SUM(AIE6:AJI6) | AJK6: 369400 | AJL6: 80000 | AJM6: 286000 | AJN6: 1304077 | AJO6: 357716 | AJP6: 655000 | AJQ6: 346923 | AJR6: 200000 | AJS6: 354960 | AJT6: 80000 | AJU6: 275389 | AJV6: 80000 | AJW6: 150000 | AJX6: 515316 | AJY6: 438000 | AJZ6: 370000 | AKA6: 130000 | AKB6: 324936 | AKC6: 551960 | AKD6: 90000 | AKE6: 355000 | AKF6: 603233 | AKG6: 870000 | AKH6: 886198 | AKI6: 250000 | AKJ6: 672000 | AKK6: 300000 | AKL6: 173000 | AKM6: =SUM(AJK6:AKL6) | AKN6: 1014000 | AKO6: 90000 | AKP6: 350000 | AKQ6: 270000 | AKR6: 100000 | AKS6: 390000 | AKT6: 600000 | AKU6: 105000 | AKV6: 495000 | AKW6: 694109 | AKX6: 320000 | AKY6: 661000 | AKZ6: 370000 | ALA6: 796980 | ALB6: 380000 | ALC6: 1454314 | ALD6: 201000 | ALF6: 1400000 | ALG6: 610000 | ALH6: 220000 | ALI6: 200000 | ALJ6: 356490 | ALK6: 752000 | ALL6: 575000 | ALM6: 450000 | ALN6: 130000 | ALO6: 854486 | ALP6: 749081 | ALQ6: 150000 | ALR6: 100000 | ALS6: =SUM(AKN6:ALR6) | ALT6: 880000 | ALU6: 290000 | ALV6: 626351 | ALW6: 205000 | ALX6: 288000 | ALY6: 813000 | ALZ6: 301515 | AMA6: 119000 | AMB6: 545000 | AMC6: 811200 | AMD6: 130000 | AME6: 50000 | AMF6: 350000 | AMG6: 474000 | AMH6: 480000 | AMI6: 260000 | AMJ6: 95000 | AMK6: 510000 | AML6: 545000 | AMM6: 390000 | AMN6: 1060000 | AMO6: 2173700 | AMP6: 803534 | AMQ6: 1381899 | AMR6: 625000 | AMS6: 575000 | AMT6: 826983 | AMU6: 277500 | AMV6: 873000 | AMW6: 214173 | AMX6: =SUM(ALT6:AMW6) | AMY6: 600000 | AMZ6: 729850 | ANA6: 80000 | ANB6: 164000 | ANC6: 974859 | AND6: 260000 | ANE6: 1992000 | ANF6: 500000 | ANG6: 831816 | ANH6: 300000 | ANI6: 110000 | ANJ6: 979848 | ANK6: 600000 | ANL6: 358586 | ANM6: 842000 | ANN6: 532500 | ANO6: 530000 | ANP6: 300000 | ANQ6: 120000 | ANR6: 520000 | ANS6: 250000 | ANT6: 605000 | ANU6: 1268689 | ANV6: 361648 | ANW6: 978000 | ANX6: 480000 | ANY6: 90000 | ANZ6: 430000 | AOA6: 959887 | AOB6: 498890 | AOC6: 585000 | AOD6: 585000
